<?xml version="1.0"?>

<robot name="rrbot" xmlns:xacro="http://www.ros.org/wiki/xacro">


    <material name="black">
        <color rgba="0 0 0 1" />
    </material>

    <material name="red">
        <color rgba="1 0 0 1" />
    </material>

    <material name="blue">
        <color rgba="0 0 1 1" />
    </material>

    <material name="green">
        <color rgba="0 1 0 1" />
    </material>


    <link name="base_link">
        <visual>
            <geometry>
                <box size="0.4 0.4 0.1" />
            </geometry>
            <material name="black" />
        </visual>
        <collision>
            <geometry>
                <box size="0.4 0.4 0.1" />
            </geometry>
        </collision>
        <inertial>
            <mass value="10" />
            <origin xyz="0 0 0" />
            <inertia ixx="0.0302083333333" ixy="0.0" ixz="0.0" iyy="0.0302083333333" iyz="0.0" izz="0.00104166666667" />
        </inertial>
    </link>

    <link name="base_link_extension">
        <visual>
            <origin xyz="0 -0.05 0.2" rpy="0 0 0" />
            <geometry>
                <box size="0.05 0.05 0.4" />
            </geometry>
            <material name="black" />
        </visual>
        <collision>
            <origin xyz="0 -0.05 0.2" rpy="0 0 0" />
            <geometry>
                <box size="0.05 0.05 0.4" />
            </geometry>
        </collision>
        <inertial>
            <mass value="10" />
            <origin xyz="0 -0.05 0.2" rpy="0 0 0" />
            <inertia ixx="0.0302083333333" ixy="0.0" ixz="0.0" iyy="0.0302083333333" iyz="0.0" izz="0.00104166666667" />
        </inertial>
    </link>

    <joint name="base_link_extension_joint" type="fixed">
        <parent link="base_link" />
        <child link="base_link_extension" />
        <origin xyz="0 0.0 0.00" rpy="0 0 0.0" />
    </joint>

    <link name="link_0">
        <visual>
            <geometry>
                <box size="0.1 0.1 0.1" />
            </geometry>
            <material name="black" />
        </visual>
        <collision>
            <geometry>
                <box size="0.1 0.1 0.1" />
            </geometry>
        </collision>
        <inertial>
            <mass value="0.5" />
            <origin xyz="0 0 0" />
            <inertia ixx="0.0302083333333" ixy="0.0" ixz="0.0" iyy="0.0302083333333" iyz="0.0" izz="0.00104166666667" />
        </inertial>
    </link>

    <joint name="joint_0" type="prismatic">
        <parent link="base_link_extension" />
        <child link="link_0" />
        <axis xyz="0 0 1" />
        <limit effort="30" velocity="1.0" lower="0" upper="0.7" />
        <origin xyz="0 0.05 0.00" rpy="0 0 1.57" />
        <dynamics damping="0.7" friction="100.0" />
    </joint>

    <link name="link_1">
        <visual>
            <origin xyz="0.2 0 0" rpy="0 0 0" />
            <geometry>
                <box size="0.4 0.1 0.1" />
            </geometry>
            <material name="blue" />
        </visual>
        <collision>
            <origin xyz="0.2 0 0" rpy="0 0 0" />
            <geometry>
                <box size="0.4 0.1 0.1" />
            </geometry>
            <material name="green" />
        </collision>
        <inertial>
            <mass value="0.5" />
            <origin xyz="0.2 0 0" />
            <inertia ixx="0.0302083333333" ixy="0.0" ixz="0.0" iyy="0.0302083333333" iyz="0.0" izz="0.00104166666667" />
        </inertial>
    </link>

    <joint name="joint_1" type="revolute">
        <parent link="link_0" />
        <child link="link_1" />
        <origin xyz="0.0 0 0.1" rpy="0 0 0" />
        <axis xyz="0 0 1" />
        <limit lower="-3.1415" upper="3.1415" effort="40" velocity="2.0" />
        <dynamics damping="0.7" friction="100.0" />

    </joint>

    <link name="link_2">
        <visual>
            <origin xyz="0.2 0 0" rpy="0 0 0" />
            <geometry>
                <box size="0.4 0.1 0.1" />
            </geometry>
            <material name="green" />
        </visual>
        <collision>
            <origin xyz="0.2 0 0" rpy="0 0 0" />
            <geometry>
                <box size="0.4 0.1 0.1" />
            </geometry>
            <material name="green" />
        </collision>
        <inertial>
            <mass value="0.5" />
            <origin xyz="0.2 0 0" />
            <inertia ixx="0.0302083333333" ixy="0.0" ixz="0.0" iyy="0.0302083333333" iyz="0.0" izz="0.00104166666667" />
        </inertial>
    </link>

    <joint name="joint_2" type="revolute">
        <parent link="link_1" />
        <child link="link_2" />
        <origin xyz="0.4 0.0 0.1" rpy="0 0 0" />
        <axis xyz="0 0 1" />
        <limit lower="-2.0" upper="2.0" effort="40" velocity="2.0" />
        <dynamics damping="0.7" friction="100.0" />

    </joint>

    <link name="tcp_link">
        <visual>
            <origin xyz="0.025 0 0" rpy="0 0 0" />
            <geometry>
                <box size="0.05 0.05 0.05" />
            </geometry>
            <material name="green" />
        </visual>
        <collision>
            <origin xyz="0 0 0" rpy="0 0 0" />
            <geometry>
                <box size="0.05 0.05 0.05" />
            </geometry>
            <material name="green" />
        </collision>
        <inertial>
            <mass value="0.05" />
            <origin xyz="0 0 0" />
            <inertia ixx="0.0302083333333" ixy="0.0" ixz="0.0" iyy="0.0302083333333" iyz="0.0" izz="0.00104166666667" />
        </inertial>
    </link>

    <joint name="tcp_joint" type="fixed">
        <parent link="link_2" />
        <child link="tcp_link" />
        <origin xyz="0.45 0.0 0.0" rpy="0 0 0" />
        <dynamics damping="10.0" friction="100.0" />

    </joint>

    <!-- ros_control plugin -->
    <ros2_control name="GazeboSystem" type="system">
        <hardware>
            <plugin>gazebo_ros2_control/GazeboSystem</plugin>
        </hardware>
        <joint name="joint_1">
            <command_interface name="position">
                <param name="min">-1</param>
                <param name="max">1</param>
            </command_interface>
            <state_interface name="position" />
            <state_interface name="velocity" />
            <state_interface name="effort" />
        </joint>
        <joint name="joint_2">
            <command_interface name="position">
                <param name="min">-1</param>
                <param name="max">1</param>
            </command_interface>
            <state_interface name="position" />
            <state_interface name="velocity" />
            <state_interface name="effort" />
        </joint>
        <joint name="joint_0">
            <command_interface name="position">
                <param name="min">-1</param>
                <param name="max">1</param>
            </command_interface>
            <state_interface name="position" />
            <state_interface name="velocity" />
            <state_interface name="effort" />
        </joint>
    </ros2_control>

    <transmission name="joint_0_trans">
        <type>transmission_interface/SimpleTransmission</type>
        <joint name="joint_0">
            <hardwareInterface>hardware_interface/EffortJointInterface</hardwareInterface>
        </joint>
        <actuator name="joint_0_motor">
            <hardwareInterface>hardware_interface/EffortJointInterface</hardwareInterface>
            <mechanicalReduction>1</mechanicalReduction>
        </actuator>
    </transmission>

    <transmission name="joint_1_trans">
        <type>transmission_interface/SimpleTransmission</type>
        <joint name="joint_1">
            <hardwareInterface>hardware_interface/EffortJointInterface</hardwareInterface>
        </joint>
        <actuator name="joint_1_motor">
            <hardwareInterface>hardware_interface/EffortJointInterface</hardwareInterface>
            <mechanicalReduction>1</mechanicalReduction>
        </actuator>
    </transmission>

    <transmission name="joint_2_trans">
        <type>transmission_interface/SimpleTransmission</type>
        <joint name="joint_2">
            <hardwareInterface>hardware_interface/EffortJointInterface</hardwareInterface>
        </joint>
        <actuator name="joint_2_motor">
            <hardwareInterface>hardware_interface/EffortJointInterface</hardwareInterface>
            <mechanicalReduction>1</mechanicalReduction>
        </actuator>
    </transmission>


    <gazebo>
        <plugin filename="libgazebo_ros2_control.so" name="gazebo_ros2_control">
            <parameters>$(find berryarm_desc)/rrbot_gazebo_forward_controller_position.yaml</parameters>
        </plugin>
    </gazebo>


    <gazebo reference="base_link_extension">
        <material>Gazebo/Red</material>
        <kp>1e07</kp>
        <kd>100.0</kd>
        <mu1>1.0</mu1>
        <mu2>1.0</mu2>
    </gazebo>
    <!-- Link1 -->
    <gazebo reference="base_link">
        <material>Gazebo/Red</material>
        <kp>1e07</kp>
        <kd>100.0</kd>
        <mu1>1.0</mu1>
        <mu2>1.0</mu2>
    </gazebo>

    <!-- Link2 -->
    <gazebo reference="link_0">
        <mu1>1.0</mu1>
        <mu2>1.0</mu2>
        <material>Gazebo/Black</material>
    </gazebo>

    <!-- Link3 -->
    <gazebo reference="link_1">
        <mu1>0.2</mu1>
        <mu2>0.2</mu2>
        <material>Gazebo/Orange</material>
    </gazebo>

    <gazebo reference="link_2">
        <mu1>0.2</mu1>
        <mu2>0.2</mu2>
        <material>Gazebo/Black</material>
    </gazebo>

    <!-- Link3 -->
    <gazebo reference="tcp_link">
        <mu1>0.2</mu1>
        <mu2>0.2</mu2>
        <material>Gazebo/Orange</material>
    </gazebo>
</robot>